Workbook

Sheet Summary
A1: Beryl (Axiom) vs C and Rust: full benchmark analysis
A2: Run 20261019T005748Z-73191bf on feat/bench-native @ 73191bf; Windows-11-10.0.26200-SP0; 8 logical CPUs
A4: Headline measure | B4: Value | C4: How it is computed
A5: Cases measured (all implementations) | B5: 579 | C5: Result records in the benchmark log
A6: Output mismatches against the reference | B6: 0 | C6: Any non-zero value would fail the run
A7: Beryl native vs C, geometric mean | B7: =GEOMEAN('Kernel times'!$L$5:$L$130) | C7: Geomean of Native/C over every case both ran (lower = Beryl faster)
A8: Beryl native vs Rust, geometric mean | B8: =GEOMEAN('Kernel times'!$M$5:$M$130) | C8: Geomean of Native/Rust over every case both ran
A9: Rust vs C, geometric mean (all kernels) | B9: =GEOMEAN('Kernel times'!$N$5:$N$130) | C9: Context: the two baselines against each other
A10: Cases where Beryl native leads C | B10: =COUNTIF('Kernel times'!$P$5:$P$130,"Lead") | C10: Native/C below 0.95x
A11: Cases at parity with C | B11: =COUNTIF('Kernel times'!$P$5:$P$130,"Parity") | C11: Native/C within 0.95x-1.05x
A12: Cases where Beryl native lags C | B12: =COUNTIF('Kernel times'!$P$5:$P$130,"Lag") | C12: Native/C above 1.05x
A13: Best native lead vs C (lowest ratio) | B13: =MIN('Kernel times'!$L$5:$L$130) | C13: conv3x3, rows-v1 plan
A14: Worst native result vs C (highest ratio) | B14: =MAX('Kernel times'!$L$5:$L$130) | C14: polymap, fully unrolled finite code
A15: Beryl interpreter vs C, geometric mean | B15: =GEOMEAN('Kernel times'!$O$5:$O$130) | C15: Checked Python interpreter path: proves every plan per request
A16: Kernel/size combinations Beryl accepts (of 42) | B16: =COUNTIFS('Kernel times'!$C$5:$C$130,"*",'Kernel times'!$S$5:$S$130,"ok",'Kernel times'!$D$5:$D$130,"hash") | C16: hash-pattern rows where the interpreter returned ok (14 kernels x 3 sizes)
A17: Median cold native compile, ms | B17: =MEDIAN('Kernel times'!$W$5:$W$130) | C17: Axiom check+emit + C compile + link for one fresh program
A18: Median Axiom check+emit share, ms | B18: =MEDIAN('Kernel times'!$X$5:$X$130) | C18: Fresh admission, ranked checked selection, C emission
A19: Native runs blocked by Windows Application Control | B19: 6 | C19: Logged as blocked, never bypassed (see Method)
A20: Bad-input rejection, ms | B20: 0.89 | C20: Out-of-range input refused before planning, via playground_service
A22: Key findings
A23: Where Beryl leads: on all five of its stencil kernels, generated native code is at or below C, and well below Rust. conv3x3 is about 4.8x faster than C because the planner chose a rolling 3-row schedule (row sums reused).
A24: Like-for-like: against hand-written C with the same ABI, shape, int32 types, harness and flags, the no-scratch plan is about 0.9x (parity, slightly faster) and the row-reuse plan about 0.5x (2x faster) because it does 256 instead of 900 multiplications.
A25: Where Beryl lags: polymap is about 1.2x slower than C. Its generated code is fully unrolled straight-line C (about 3,400 statements) plus a 256-cell range check per call, while the C baseline is a short vectorizable loop.
A26: Where Beryl lacks: it accepts 6 of 42 kernel/size combinations. Every medium and large case is blocked by the 256-cell limit, and 8 kernels need language features it does not have (reductions, scans, scatter, conditionals, max, permuted reads).
A27: The interpreter is not a speed path: it re-proves every plan on each request, about 5 orders of magnitude slower than C. It exists so every playground result is independently checked.
A28: Caveat: shape-specialized generated kernels with int32 outputs are compared with runtime-sized C/Rust baselines that store int64 outputs; the hand-C control (sq2x2) separates that effect. Single machine, small sizes, call overhead dominates.
A30: Sheets
A31: Kernel times | C31: Every kernel x size x pattern, all four implementations, ratios and verdicts (filterable)
A32: Like-for-like | C32: Beryl native vs hand-written C with identical terms, across storage caps
A33: Plan sweep | C33: Same program under different storage caps and objectives: plan, work, time
A34: Interpreter phases | C34: Where the checked interpreter spends its time
A35: Coverage | C35: What Beryl accepts, per kernel and size, and the missing features ranked
A36: Lead-lag analysis | C36: Per kernel: where we lead or lag, why, confidence, and what would change it
A37: Improvement roadmap | C37: Prioritized improvements tied to the evidence
A38: Method | C38: Environment, toolchains, protocol, verification and caveats
A39: Raw results | C39: Flattened analysis rows for further analysis

Sheet Kernel times
A1: Median time per call (ns) for every kernel, size and input pattern
A2: Blue = measured inputs from the benchmark log; black = Excel formulas. Ratios below 1.00x mean the first-named runs faster.
A4: Kernel | B4: Family | C4: Size | D4: Pattern | E4: Params (a,b) | F4: Outputs | G4: C ns | H4: Rust ns | I4: Beryl native ns | J4: Beryl interpreter ns | K4: Hand C ns (same terms) | L4: Native / C | M4: Native / Rust | N4: Rust / C | O4: Interpreter / C | P4: Verdict vs C | Q4: Verdict vs Rust | R4: Native status | S4: Interpreter status | T4: Plan | U4: Mults | V4: Scratch B | W4: Compile ms | X4: Check+emit ms | Y4: cc ms | Z4: Interp. pipeline ms | AA4: Axiom diagnostic / missing | AB4: Verified
A5: sq2x2 | B5: stencil-2d | C5: s | D5: hash | E5: 15,15 | F5: 225 | G5: 422 | H5: 878 | I5: 305 | J5: 118945500 | K5: 430 | L5: =IF(AND(ISNUMBER(I5),ISNUMBER(G5)),I5/G5,"") | M5: =IF(AND(ISNUMBER(I5),ISNUMBER(H5)),I5/H5,"") | N5: =IF(AND(ISNUMBER(H5),ISNUMBER(G5)),H5/G5,"") | O5: =IF(AND(ISNUMBER(J5),ISNUMBER(G5)),J5/G5,"") | P5: =IF(L5="","n/a",IF(L5<0.95,"Lead",IF(L5>1.05,"Lag","Parity"))) | Q5: =IF(M5="","n/a",IF(M5<0.95,"Lead",IF(M5>1.05,"Lag","Parity"))) | R5: ok | S5: ok | T5: inline-v1 | U5: 900 | V5: 0 | W5: 567.2 | X5: 160 | Y5: 407.2 | Z5: 391.5 | AB5: yes
A6: sq2x2 | B6: stencil-2d | C6: s | D6: max | E6: 15,15 | F6: 225 | G6: 513 | H6: 897 | I6: 407 | J6: 129022600 | K6: 420 | L6: =IF(AND(ISNUMBER(I6),ISNUMBER(G6)),I6/G6,"") | M6: =IF(AND(ISNUMBER(I6),ISNUMBER(H6)),I6/H6,"") | N6: =IF(AND(ISNUMBER(H6),ISNUMBER(G6)),H6/G6,"") | O6: =IF(AND(ISNUMBER(J6),ISNUMBER(G6)),J6/G6,"") | P6: =IF(L6="","n/a",IF(L6<0.95,"Lead",IF(L6>1.05,"Lag","Parity"))) | Q6: =IF(M6="","n/a",IF(M6<0.95,"Lead",IF(M6>1.05,"Lag","Parity"))) | R6: ok | S6: ok | T6: inline-v1 | U6: 900 | V6: 0 | W6: 367.3 | X6: 124 | Y6: 243.4 | Z6: 323.7 | AB6: yes
A7: sq2x2 | B7: stencil-2d | C7: s | D7: ramp | E7: 15,15 | F7: 225 | G7: 388 | H7: 719 | I7: 364 | J7: 118987300 | K7: 342 | L7: =IF(AND(ISNUMBER(I7),ISNUMBER(G7)),I7/G7,"") | M7: =IF(AND(ISNUMBER(I7),ISNUMBER(H7)),I7/H7,"") | N7: =IF(AND(ISNUMBER(H7),ISNUMBER(G7)),H7/G7,"") | O7: =IF(AND(ISNUMBER(J7),ISNUMBER(G7)),J7/G7,"") | P7: =IF(L7="","n/a",IF(L7<0.95,"Lead",IF(L7>1.05,"Lag","Parity"))) | Q7: =IF(M7="","n/a",IF(M7<0.95,"Lead",IF(M7>1.05,"Lag","Parity"))) | R7: ok | S7: ok | T7: inline-v1 | U7: 900 | V7: 0 | W7: 410.1 | X7: 121.2 | Y7: 288.9 | Z7: 325.8 | AB7: yes
A8: sq2x2 | B8: stencil-2d | C8: m | D8: hash | E8: 255,255 | F8: 65025 | G8: 148700 | H8: 200375 | L8: =IF(AND(ISNUMBER(I8),ISNUMBER(G8)),I8/G8,"") | M8: =IF(AND(ISNUMBER(I8),ISNUMBER(H8)),I8/H8,"") | N8: =IF(AND(ISNUMBER(H8),ISNUMBER(G8)),H8/G8,"") | O8: =IF(AND(ISNUMBER(J8),ISNUMBER(G8)),J8/G8,"") | P8: =IF(L8="","n/a",IF(L8<0.95,"Lead",IF(L8>1.05,"Lag","Parity"))) | Q8: =IF(M8="","n/a",IF(M8<0.95,"Lead",IF(M8>1.05,"Lag","Parity"))) | R8: unsupported | S8: unsupported | AA8: UNSUPPORTED_PROFILE / input exceeds 256 cells | AB8: yes
A9: sq2x2 | B9: stencil-2d | C9: m | D9: max | E9: 255,255 | F9: 65025 | G9: 156225 | H9: 198712 | L9: =IF(AND(ISNUMBER(I9),ISNUMBER(G9)),I9/G9,"") | M9: =IF(AND(ISNUMBER(I9),ISNUMBER(H9)),I9/H9,"") | N9: =IF(AND(ISNUMBER(H9),ISNUMBER(G9)),H9/G9,"") | O9: =IF(AND(ISNUMBER(J9),ISNUMBER(G9)),J9/G9,"") | P9: =IF(L9="","n/a",IF(L9<0.95,"Lead",IF(L9>1.05,"Lag","Parity"))) | Q9: =IF(M9="","n/a",IF(M9<0.95,"Lead",IF(M9>1.05,"Lag","Parity"))) | R9: unsupported | S9: unsupported | AA9: UNSUPPORTED_PROFILE / input exceeds 256 cells | AB9: yes
A10: sq2x2 | B10: stencil-2d | C10: m | D10: ramp | E10: 255,255 | F10: 65025 | G10: 144312 | H10: 185712 | L10: =IF(AND(ISNUMBER(I10),ISNUMBER(G10)),I10/G10,"") | M10: =IF(AND(ISNUMBER(I10),ISNUMBER(H10)),I10/H10,"") | N10: =IF(AND(ISNUMBER(H10),ISNUMBER(G10)),H10/G10,"") | O10: =IF(AND(ISNUMBER(J10),ISNUMBER(G10)),J10/G10,"") | P10: =IF(L10="","n/a",IF(L10<0.95,"Lead",IF(L10>1.05,"Lag","Parity"))) | Q10: =IF(M10="","n/a",IF(M10<0.95,"Lead",IF(M10>1.05,"Lag","Parity"))) | R10: unsupported | S10: unsupported | AA10: UNSUPPORTED_PROFILE / input exceeds 256 cells | AB10: yes
A11: sq2x2 | B11: stencil-2d | C11: l | D11: hash | E11: 2047,2047 | F11: 4190209 | G11: 8373650 | H11: 12651850 | L11: =IF(AND(ISNUMBER(I11),ISNUMBER(G11)),I11/G11,"") | M11: =IF(AND(ISNUMBER(I11),ISNUMBER(H11)),I11/H11,"") | N11: =IF(AND(ISNUMBER(H11),ISNUMBER(G11)),H11/G11,"") | O11: =IF(AND(ISNUMBER(J11),ISNUMBER(G11)),J11/G11,"") | P11: =IF(L11="","n/a",IF(L11<0.95,"Lead",IF(L11>1.05,"Lag","Parity"))) | Q11: =IF(M11="","n/a",IF(M11<0.95,"Lead",IF(M11>1.05,"Lag","Parity"))) | R11: unsupported | S11: unsupported | AA11: UNSUPPORTED_PROFILE / input exceeds 256 cells | AB11: yes
A12: sq2x2 | B12: stencil-2d | C12: l | D12: max | E12: 2047,2047 | F12: 4190209 | G12: 10026850 | H12: 13721300 | L12: =IF(AND(ISNUMBER(I12),ISNUMBER(G12)),I12/G12,"") | M12: =IF(AND(ISNUMBER(I12),ISNUMBER(H12)),I12/H12,"") | N12: =IF(AND(ISNUMBER(H12),ISNUMBER(G12)),H12/G12,"") | O12: =IF(AND(ISNUMBER(J12),ISNUMBER(G12)),J12/G12,"") | P12: =IF(L12="","n/a",IF(L12<0.95,"Lead",IF(L12>1.05,"Lag","Parity"))) | Q12: =IF(M12="","n/a",IF(M12<0.95,"Lead",IF(M12>1.05,"Lag","Parity"))) | R12: unsupported | S12: unsupported | AA12: UNSUPPORTED_PROFILE / input exceeds 256 cells | AB12: yes
A13: sq2x2 | B13: stencil-2d | C13: l | D13: ramp | E13: 2047,2047 | F13: 4190209 | G13: 8003000 | H13: 13138300 | L13: =IF(AND(ISNUMBER(I13),ISNUMBER(G13)),I13/G13,"") | M13: =IF(AND(ISNUMBER(I13),ISNUMBER(H13)),I13/H13,"") | N13: =IF(AND(ISNUMBER(H13),ISNUMBER(G13)),H13/G13,"") | O13: =IF(AND(ISNUMBER(J13),ISNUMBER(G13)),J13/G13,"") | P13: =IF(L13="","n/a",IF(L13<0.95,"Lead",IF(L13>1.05,"Lag","Parity"))) | Q13: =IF(M13="","n/a",IF(M13<0.95,"Lead",IF(M13>1.05,"Lag","Parity"))) | R13: unsupported | S13: unsupported | AA13: UNSUPPORTED_PROFILE / input exceeds 256 cells | AB13: yes
A14: stencil1d3 | B14: stencil-1d | C14: s | D14: hash | E14: 254,0 | F14: 254 | G14: 206 | H14: 162 | I14: 164 | J14: 59255900 | L14: =IF(AND(ISNUMBER(I14),ISNUMBER(G14)),I14/G14,"") | M14: =IF(AND(ISNUMBER(I14),ISNUMBER(H14)),I14/H14,"") | N14: =IF(AND(ISNUMBER(H14),ISNUMBER(G14)),H14/G14,"") | O14: =IF(AND(ISNUMBER(J14),ISNUMBER(G14)),J14/G14,"") | P14: =IF(L14="","n/a",IF(L14<0.95,"Lead",IF(L14>1.05,"Lag","Parity"))) | Q14: =IF(M14="","n/a",IF(M14<0.95,"Lead",IF(M14>1.05,"Lag","Parity"))) | R14: ok | S14: ok | T14: inline-v1 | U14: 254 | V14: 0 | W14: 758.8 | X14: 104 | Y14: 654.7 | Z14: 220.8 | AB14: yes
A15: stencil1d3 | B15: stencil-1d | C15: s | D15: max | E15: 254,0 | F15: 254 | G15: 187 | H15: 205 | J15: 55730500 | L15: =IF(AND(ISNUMBER(I15),ISNUMBER(G15)),I15/G15,"") | M15: =IF(AND(ISNUMBER(I15),ISNUMBER(H15)),I15/H15,"") | N15: =IF(AND(ISNUMBER(H15),ISNUMBER(G15)),H15/G15,"") | O15: =IF(AND(ISNUMBER(J15),ISNUMBER(G15)),J15/G15,"") | P15: =IF(L15="","n/a",IF(L15<0.95,"Lead",IF(L15>1.05,"Lag","Parity"))) | Q15: =IF(M15="","n/a",IF(M15<0.95,"Lead",IF(M15>1.05,"Lag","Parity"))) | R15: blocked | S15: ok | Z15: 202.4 | AB15: yes
A16: stencil1d3 | B16: stencil-1d | C16: s | D16: ramp | E16: 254,0 | F16: 254 | G16: 162 | H16: 155 | I16: 162 | J16: 44709000 | L16: =IF(AND(ISNUMBER(I16),ISNUMBER(G16)),I16/G16,"") | M16: =IF(AND(ISNUMBER(I16),ISNUMBER(H16)),I16/H16,"") | N16: =IF(AND(ISNUMBER(H16),ISNUMBER(G16)),H16/G16,"") | O16: =IF(AND(ISNUMBER(J16),ISNUMBER(G16)),J16/G16,"") | P16: =IF(L16="","n/a",IF(L16<0.95,"Lead",IF(L16>1.05,"Lag","Parity"))) | Q16: =IF(M16="","n/a",IF(M16<0.95,"Lead",IF(M16>1.05,"Lag","Parity"))) | R16: ok | S16: ok | T16: inline-v1 | U16: 254 | V16: 0 | W16: 404.6 | X16: 63.5 | Y16: 341.1 | Z16: 181.6 | AB16: yes
A17: stencil1d3 | B17: stencil-1d | C17: m | D17: hash | E17: 65534,0 | F17: 65534 | G17: 52643 | H17: 50351 | L17: =IF(AND(ISNUMBER(I17),ISNUMBER(G17)),I17/G17,"") | M17: =IF(AND(ISNUMBER(I17),ISNUMBER(H17)),I17/H17,"") | N17: =IF(AND(ISNUMBER(H17),ISNUMBER(G17)),H17/G17,"") | O17: =IF(AND(ISNUMBER(J17),ISNUMBER(G17)),J17/G17,"") | P17: =IF(L17="","n/a",IF(L17<0.95,"Lead",IF(L17>1.05,"Lag","Parity"))) | Q17: =IF(M17="","n/a",IF(M17<0.95,"Lead",IF(M17>1.05,"Lag","Parity"))) | R17: unsupported | S17: unsupported | AA17: UNSUPPORTED_PROFILE / input exceeds 256 cells | AB17: yes
A18: stencil1d3 | B18: stencil-1d | C18: m | D18: max | E18: 65534,0 | F18: 65534 | G18: 45625 | H18: 39821 | L18: =IF(AND(ISNUMBER(I18),ISNUMBER(G18)),I18/G18,"") | M18: =IF(AND(ISNUMBER(I18),ISNUMBER(H18)),I18/H18,"") | N18: =IF(AND(ISNUMBER(H18),ISNUMBER(G18)),H18/G18,"") | O18: =IF(AND(ISNUMBER(J18),ISNUMBER(G18)),J18/G18,"") | P18: =IF(L18="","n/a",IF(L18<0.95,"Lead",IF(L18>1.05,"Lag","Parity"))) | Q18: =IF(M18="","n/a",IF(M18<0.95,"Lead",IF(M18>1.05,"Lag","Parity"))) | R18: unsupported | S18: unsupported | AA18: UNSUPPORTED_PROFILE / input exceeds 256 cells | AB18: yes
A19: stencil1d3 | B19: stencil-1d | C19: m | D19: ramp | E19: 65534,0 | F19: 65534 | G19: 44259 | H19: 51103 | L19: =IF(AND(ISNUMBER(I19),ISNUMBER(G19)),I19/G19,"") | M19: =IF(AND(ISNUMBER(I19),ISNUMBER(H19)),I19/H19,"") | N19: =IF(AND(ISNUMBER(H19),ISNUMBER(G19)),H19/G19,"") | O19: =IF(AND(ISNUMBER(J19),ISNUMBER(G19)),J19/G19,"") | P19: =IF(L19="","n/a",IF(L19<0.95,"Lead",IF(L19>1.05,"Lag","Parity"))) | Q19: =IF(M19="","n/a",IF(M19<0.95,"Lead",IF(M19>1.05,"Lag","Parity"))) | R19: unsupported | S19: unsupported | AA19: UNSUPPORTED_PROFILE / input exceeds 256 cells | AB19: yes
A20: stencil1d3 | B20: stencil-1d | C20: l | D20: hash | E20: 4194302,0 | F20: 4194302 | G20: 4415300 | H20: 4491700 | L20: =IF(AND(ISNUMBER(I20),ISNUMBER(G20)),I20/G20,"") | M20: =IF(AND(ISNUMBER(I20),ISNUMBER(H20)),I20/H20,"") | N20: =IF(AND(ISNUMBER(H20),ISNUMBER(G20)),H20/G20,"") | O20: =IF(AND(ISNUMBER(J20),ISNUMBER(G20)),J20/G20,"") | P20: =IF(L20="","n/a",IF(L20<0.95,"Lead",IF(L20>1.05,"Lag","Parity"))) | Q20: =IF(M20="","n/a",IF(M20<0.95,"Lead",IF(M20>1.05,"Lag","Parity"))) | R20: unsupported | S20: unsupported | AA20: UNSUPPORTED_PROFILE / input exceeds 256 cells | AB20: yes
A21: stencil1d3 | B21: stencil-1d | C21: l | D21: max | E21: 4194302,0 | F21: 4194302 | G21: 5291400 | H21: 5853100 | L21: =IF(AND(ISNUMBER(I21),ISNUMBER(G21)),I21/G21,"") | M21: =IF(AND(ISNUMBER(I21),ISNUMBER(H21)),I21/H21,"") | N21: =IF(AND(ISNUMBER(H21),ISNUMBER(G21)),H21/G21,"") | O21: =IF(AND(ISNUMBER(J21),ISNUMBER(G21)),J21/G21,"") | P21: =IF(L21="","n/a",IF(L21<0.95,"Lead",IF(L21>1.05,"Lag","Parity"))) | Q21: =IF(M21="","n/a",IF(M21<0.95,"Lead",IF(M21>1.05,"Lag","Parity"))) | R21: unsupported | S21: unsupported | AA21: UNSUPPORTED_PROFILE / input exceeds 256 cells | AB21: yes
A22: stencil1d3 | B22: stencil-1d | C22: l | D22: ramp | E22: 4194302,0 | F22: 4194302 | G22: 4595350 | H22: 4006400 | L22: =IF(AND(ISNUMBER(I22),ISNUMBER(G22)),I22/G22,"") | M22: =IF(AND(ISNUMBER(I22),ISNUMBER(H22)),I22/H22,"") | N22: =IF(AND(ISNUMBER(H22),ISNUMBER(G22)),H22/G22,"") | O22: =IF(AND(ISNUMBER(J22),ISNUMBER(G22)),J22/G22,"") | P22: =IF(L22="","n/a",IF(L22<0.95,"Lead",IF(L22>1.05,"Lag","Parity"))) | Q22: =IF(M22="","n/a",IF(M22<0.95,"Lead",IF(M22>1.05,"Lag","Parity"))) | R22: unsupported | S22: unsupported | AA22: UNSUPPORTED_PROFILE / input exceeds 256 cells | AB22: yes
A23: box3x3 | B23: stencil-2d | C23: s | D23: hash | E23: 14,14 | F23: 196 | G23: 482 | H23: 502 | I23: 311 | J23: 89714900 | L23: =IF(AND(ISNUMBER(I23),ISNUMBER(G23)),I23/G23,"") | M23: =IF(AND(ISNUMBER(I23),ISNUMBER(H23)),I23/H23,"") | N23: =IF(AND(ISNUMBER(H23),ISNUMBER(G23)),H23/G23,"") | O23: =IF(AND(ISNUMBER(J23),ISNUMBER(G23)),J23/G23,"") | P23: =IF(L23="","n/a",IF(L23<0.95,"Lead",IF(L23>1.05,"Lag","Parity"))) | Q23: =IF(M23="","n/a",IF(M23<0.95,"Lead",IF(M23>1.05,"Lag","Parity"))) | R23: ok | S23: ok | T23: inline-v1 | U23: 0 | V23: 0 | W23: 604.4 | X23: 96.3 | Y23: 508.1 | Z23: 286.1 | AB23: yes
A24: box3x3 | B24: stencil-2d | C24: s | D24: max | E24: 14,14 | F24: 196 | G24: 346 | H24: 419 | I24: 307 | J24: 88115200 | L24: =IF(AND(ISNUMBER(I24),ISNUMBER(G24)),I24/G24,"") | M24: =IF(AND(ISNUMBER(I24),ISNUMBER(H24)),I24/H24,"") | N24: =IF(AND(ISNUMBER(H24),ISNUMBER(G24)),H24/G24,"") | O24: =IF(AND(ISNUMBER(J24),ISNUMBER(G24)),J24/G24,"") | P24: =IF(L24="","n/a",IF(L24<0.95,"Lead",IF(L24>1.05,"Lag","Parity"))) | Q24: =IF(M24="","n/a",IF(M24<0.95,"Lead",IF(M24>1.05,"Lag","Parity"))) | R24: ok | S24: ok | T24: inline-v1 | U24: 0 | V24: 0 | W24: 497.7 | X24: 85.5 | Y24: 412.2 | Z24: 282.4 | AB24: yes
A25: box3x3 | B25: stencil-2d | C25: s | D25: ramp | E25: 14,14 | F25: 196 | G25: 349 | H25: 506 | I25: 305 | J25: 136965400 | L25: =IF(AND(ISNUMBER(I25),ISNUMBER(G25)),I25/G25,"") | M25: =IF(AND(ISNUMBER(I25),ISNUMBER(H25)),I25/H25,"") | N25: =IF(AND(ISNUMBER(H25),ISNUMBER(G25)),H25/G25,"") | O25: =IF(AND(ISNUMBER(J25),ISNUMBER(G25)),J25/G25,"") | P25: =IF(L25="","n/a",IF(L25<0.95,"Lead",IF(L25>1.05,"Lag","Parity"))) | Q25: =IF(M25="","n/a",IF(M25<0.95,"Lead",IF(M25>1.05,"Lag","Parity"))) | R25: ok | S25: ok | T25: inline-v1 | U25: 0 | V25: 0 | W25: 573.4 | X25: 109.5 | Y25: 463.8 | Z25: 354.9 | AB25: yes
A26: box3x3 | B26: stencil-2d | C26: m | D26: hash | E26: 254,254 | F26: 64516 | G26: 115406 | H26: 55337 | L26: =IF(AND(ISNUMBER(I26),ISNUMBER(G26)),I26/G26,"") | M26: =IF(AND(ISNUMBER(I26),ISNUMBER(H26)),I26/H26,"") | N26: =IF(AND(ISNUMBER(H26),ISNUMBER(G26)),H26/G26,"") | O26: =IF(AND(ISNUMBER(J26),ISNUMBER(G26)),J26/G26,"") | P26: =IF(L26="","n/a",IF(L26<0.95,"Lead",IF(L26>1.05,"Lag","Parity"))) | Q26: =IF(M26="","n/a",IF(M26<0.95,"Lead",IF(M26>1.05,"Lag","Parity"))) | R26: unsupported | S26: unsupported | AA26: UNSUPPORTED_PROFILE / input exceeds 256 cells | AB26: yes
A27: box3x3 | B27: stencil-2d | C27: m | D27: max | E27: 254,254 | F27: 64516 | G27: 104887 | H27: 77237 | L27: =IF(AND(ISNUMBER(I27),ISNUMBER(G27)),I27/G27,"") | M27: =IF(AND(ISNUMBER(I27),ISNUMBER(H27)),I27/H27,"") | N27: =IF(AND(ISNUMBER(H27),ISNUMBER(G27)),H27/G27,"") | O27: =IF(AND(ISNUMBER(J27),ISNUMBER(G27)),J27/G27,"") | P27: =IF(L27="","n/a",IF(L27<0.95,"Lead",IF(L27>1.05,"Lag","Parity"))) | Q27: =IF(M27="","n/a",IF(M27<0.95,"Lead",IF(M27>1.05,"Lag","Parity"))) | R27: unsupported | S27: unsupported | AA27: UNSUPPORTED_PROFILE / input exceeds 256 cells | AB27: yes
A28: box3x3 | B28: stencil-2d | C28: m | D28: ramp | E28: 254,254 | F28: 64516 | G28: 104212 | H28: 62701 | L28: =IF(AND(ISNUMBER(I28),ISNUMBER(G28)),I28/G28,"") | M28: =IF(AND(ISNUMBER(I28),ISNUMBER(H28)),I28/H28,"") | N28: =IF(AND(ISNUMBER(H28),ISNUMBER(G28)),H28/G28,"") | O28: =IF(AND(ISNUMBER(J28),ISNUMBER(G28)),J28/G28,"") | P28: =IF(L28="","n/a",IF(L28<0.95,"Lead",IF(L28>1.05,"Lag","Parity"))) | Q28: =IF(M28="","n/a",IF(M28<0.95,"Lead",IF(M28>1.05,"Lag","Parity"))) | R28: unsupported | S28: unsupported | AA28: UNSUPPORTED_PROFILE / input exceeds 256 cells | AB28: yes
A29: box3x3 | B29: stencil-2d | C29: l | D29: hash | E29: 2046,2046 | F29: 4186116 | G29: 6969000 | H29: 4227100 | L29: =IF(AND(ISNUMBER(I29),ISNUMBER(G29)),I29/G29,"") | M29: =IF(AND(ISNUMBER(I29),ISNUMBER(H29)),I29/H29,"") | N29: =IF(AND(ISNUMBER(H29),ISNUMBER(G29)),H29/G29,"") | O29: =IF(AND(ISNUMBER(J29),ISNUMBER(G29)),J29/G29,"") | P29: =IF(L29="","n/a",IF(L29<0.95,"Lead",IF(L29>1.05,"Lag","Parity"))) | Q29: =IF(M29="","n/a",IF(M29<0.95,"Lead",IF(M29>1.05,"Lag","Parity"))) | R29: unsupported | S29: unsupported | AA29: UNSUPPORTED_PROFILE / input exceeds 256 cells | AB29: yes
A30: box3x3 | B30: stencil-2d | C30: l | D30: max | E30: 2046,2046 | F30: 4186116 | G30: 7051400 | H30: 4572500 | L30: =IF(AND(ISNUMBER(I30),ISNUMBER(G30)),I30/G30,"") | M30: =IF(AND(ISNUMBER(I30),ISNUMBER(H30)),I30/H30,"") | N30: =IF(AND(ISNUMBER(H30),ISNUMBER(G30)),H30/G30,"") | O30: =IF(AND(ISNUMBER(J30),ISNUMBER(G30)),J30/G30,"") | P30: =IF(L30="","n/a",IF(L30<0.95,"Lead",IF(L30>1.05,"Lag","Parity"))) | Q30: =IF(M30="","n/a",IF(M30<0.95,"Lead",IF(M30>1.05,"Lag","Parity"))) | R30: unsupported | S30: unsupported | AA30: UNSUPPORTED_PROFILE / input exceeds 256 cells | AB30: yes
A31: box3x3 | B31: stencil-2d | C31: l | D31: ramp | E31: 2046,2046 | F31: 4186116 | G31: 7203250 | H31: 4348000 | L31: =IF(AND(ISNUMBER(I31),ISNUMBER(G31)),I31/G31,"") | M31: =IF(AND(ISNUMBER(I31),ISNUMBER(H31)),I31/H31,"") | N31: =IF(AND(ISNUMBER(H31),ISNUMBER(G31)),H31/G31,"") | O31: =IF(AND(ISNUMBER(J31),ISNUMBER(G31)),J31/G31,"") | P31: =IF(L31="","n/a",IF(L31<0.95,"Lead",IF(L31>1.05,"Lag","Parity"))) | Q31: =IF(M31="","n/a",IF(M31<0.95,"Lead",IF(M31>1.05,"Lag","Parity"))) | R31: unsupported | S31: unsupported | AA31: UNSUPPORTED_PROFILE / input exceeds 256 cells | AB31: yes
A32: laplace5 | B32: stencil-2d | C32: s | D32: hash | E32: 14,14 | F32: 196 | G32: 227 | H32: 348 | I32: 209 | J32: 79860400 | L32: =IF(AND(ISNUMBER(I32),ISNUMBER(G32)),I32/G32,"") | M32: =IF(AND(ISNUMBER(I32),ISNUMBER(H32)),I32/H32,"") | N32: =IF(AND(ISNUMBER(H32),ISNUMBER(G32)),H32/G32,"") | O32: =IF(AND(ISNUMBER(J32),ISNUMBER(G32)),J32/G32,"") | P32: =IF(L32="","n/a",IF(L32<0.95,"Lead",IF(L32>1.05,"Lag","Parity"))) | Q32: =IF(M32="","n/a",IF(M32<0.95,"Lead",IF(M32>1.05,"Lag","Parity"))) | R32: ok | S32: ok | T32: inline-v1 | U32: 980 | V32: 0 | W32: 469 | X32: 101.9 | Y32: 367.1 | Z32: 309.1 | AB32: yes
A33: laplace5 | B33: stencil-2d | C33: s | D33: max | E33: 14,14 | F33: 196 | G33: 227 | H33: 349 | I33: 199 | J33: 83811000 | L33: =IF(AND(ISNUMBER(I33),ISNUMBER(G33)),I33/G33,"") | M33: =IF(AND(ISNUMBER(I33),ISNUMBER(H33)),I33/H33,"") | N33: =IF(AND(ISNUMBER(H33),ISNUMBER(G33)),H33/G33,"") | O33: =IF(AND(ISNUMBER(J33),ISNUMBER(G33)),J33/G33,"") | P33: =IF(L33="","n/a",IF(L33<0.95,"Lead",IF(L33>1.05,"Lag","Parity"))) | Q33: =IF(M33="","n/a",IF(M33<0.95,"Lead",IF(M33>1.05,"Lag","Parity"))) | R33: ok | S33: ok | T33: inline-v1 | U33: 980 | V33: 0 | W33: 512.9 | X33: 108.8 | Y33: 404.2 | Z33: 321.9 | AB33: yes
A34: laplace5 | B34: stencil-2d | C34: s | D34: ramp | E34: 14,14 | F34: 196 | G34: 228 | H34: 402 | I34: 197 | J34: 80631700 | L34: =IF(AND(ISNUMBER(I34),ISNUMBER(G34)),I34/G34,"") | M34: =IF(AND(ISNUMBER(I34),ISNUMBER(H34)),I34/H34,"") | N34: =IF(AND(ISNUMBER(H34),ISNUMBER(G34)),H34/G34,"") | O34: =IF(AND(ISNUMBER(J34),ISNUMBER(G34)),J34/G34,"") | P34: =IF(L34="","n/a",IF(L34<0.95,"Lead",IF(L34>1.05,"Lag","Parity"))) | Q34: =IF(M34="","n/a",IF(M34<0.95,"Lead",IF(M34>1.05,"Lag","Parity"))) | R34: ok | S34: ok | T34: inline-v1 | U34: 980 | V34: 0 | W34: 475.1 | X34: 101.3 | Y34: 373.7 | Z34: 313.5 | AB34: yes
A35: laplace5 | B35: stencil-2d | C35: m | D35: hash | E35: 254,254 | F35: 64516 | G35: 65287 | H35: 64884 | L35: =IF(AND(ISNUMBER(I35),ISNUMBER(G35)),I35/G35,"") | M35: =IF(AND(ISNUMBER(I35),ISNUMBER(H35)),I35/H35,"") | N35: =IF(AND(ISNUMBER(H35),ISNUMBER(G35)),H35/G35,"") | O35: =IF(AND(ISNUMBER(J35),ISNUMBER(G35)),J35/G35,"") | P35: =IF(L35="","n/a",IF(L35<0.95,"Lead",IF(L35>1.05,"Lag","Parity"))) | Q35: =IF(M35="","n/a",IF(M35<0.95,"Lead",IF(M35>1.05,"Lag","Parity"))) | R35: unsupported | S35: unsupported | AA35: UNSUPPORTED_PROFILE / input exceeds 256 cells | AB35: yes
A36: laplace5 | B36: stencil-2d | C36: m | D36: max | E36: 254,254 | F36: 64516 | G36: 65312 | H36: 64862 | L36: =IF(AND(ISNUMBER(I36),ISNUMBER(G36)),I36/G36,"") | M36: =IF(AND(ISNUMBER(I36),ISNUMBER(H36)),I36/H36,"") | N36: =IF(AND(ISNUMBER(H36),ISNUMBER(G36)),H36/G36,"") | O36: =IF(AND(ISNUMBER(J36),ISNUMBER(G36)),J36/G36,"") | P36: =IF(L36="","n/a",IF(L36<0.95,"Lead",IF(L36>1.05,"Lag","Parity"))) | Q36: =IF(M36="","n/a",IF(M36<0.95,"Lead",IF(M36>1.05,"Lag","Parity"))) | R36: unsupported | S36: unsupported | AA36: UNSUPPORTED_PROFILE / input exceeds 256 cells | AB36: yes
A37: laplace5 | B37: stencil-2d | C37: m | D37: ramp | E37: 254,254 | F37: 64516 | G37: 65652 | H37: 65131 | L37: =IF(AND(ISNUMBER(I37),ISNUMBER(G37)),I37/G37,"") | M37: =IF(AND(ISNUMBER(I37),ISNUMBER(H37)),I37/H37,"") | N37: =IF(AND(ISNUMBER(H37),ISNUMBER(G37)),H37/G37,"") | O37: =IF(AND(ISNUMBER(J37),ISNUMBER(G37)),J37/G37,"") | P37: =IF(L37="","n/a",IF(L37<0.95,"Lead",IF(L37>1.05,"Lag","Parity"))) | Q37: =IF(M37="","n/a",IF(M37<0.95,"Lead",IF(M37>1.05,"Lag","Parity"))) | R37: unsupported | S37: unsupported | AA37: UNSUPPORTED_PROFILE / input exceeds 256 cells | AB37: yes
A38: laplace5 | B38: stencil-2d | C38: l | D38: hash | E38: 2046,2046 | F38: 4186116 | G38: 4658600 | H38: 4660900 | L38: =IF(AND(ISNUMBER(I38),ISNUMBER(G38)),I38/G38,"") | M38: =IF(AND(ISNUMBER(I38),ISNUMBER(H38)),I38/H38,"") | N38: =IF(AND(ISNUMBER(H38),ISNUMBER(G38)),H38/G38,"") | O38: =IF(AND(ISNUMBER(J38),ISNUMBER(G38)),J38/G38,"") | P38: =IF(L38="","n/a",IF(L38<0.95,"Lead",IF(L38>1.05,"Lag","Parity"))) | Q38: =IF(M38="","n/a",IF(M38<0.95,"Lead",IF(M38>1.05,"Lag","Parity"))) | R38: unsupported | S38: unsupported | AA38: UNSUPPORTED_PROFILE / input exceeds 256 cells | AB38: yes
A39: laplace5 | B39: stencil-2d | C39: l | D39: max | E39: 2046,2046 | F39: 4186116 | G39: 8493700 | H39: 6446300 | L39: =IF(AND(ISNUMBER(I39),ISNUMBER(G39)),I39/G39,"") | M39: =IF(AND(ISNUMBER(I39),ISNUMBER(H39)),I39/H39,"") | N39: =IF(AND(ISNUMBER(H39),ISNUMBER(G39)),H39/G39,"") | O39: =IF(AND(ISNUMBER(J39),ISNUMBER(G39)),J39/G39,"") | P39: =IF(L39="","n/a",IF(L39<0.95,"Lead",IF(L39>1.05,"Lag","Parity"))) | Q39: =IF(M39="","n/a",IF(M39<0.95,"Lead",IF(M39>1.05,"Lag","Parity"))) | R39: unsupported | S39: unsupported | AA39: UNSUPPORTED_PROFILE / input exceeds 256 cells | AB39: yes
A40: laplace5 | B40: stencil-2d | C40: l | D40: ramp | E40: 2046,2046 | F40: 4186116 | G40: 4914650 | H40: 4754850 | L40: =IF(AND(ISNUMBER(I40),ISNUMBER(G40)),I40/G40,"") | M40: =IF(AND(ISNUMBER(I40),ISNUMBER(H40)),I40/H40,"") | N40: =IF(AND(ISNUMBER(H40),ISNUMBER(G40)),H40/G40,"") | O40: =IF(AND(ISNUMBER(J40),ISNUMBER(G40)),J40/G40,"") | P40: =IF(L40="","n/a",IF(L40<0.95,"Lead",IF(L40>1.05,"Lag","Parity"))) | Q40: =IF(M40="","n/a",IF(M40<0.95,"Lead",IF(M40>1.05,"Lag","Parity"))) | R40: unsupported | S40: unsupported | AA40: UNSUPPORTED_PROFILE / input exceeds 256 cells | AB40: yes
A41: conv3x3 | B41: stencil-2d | C41: s | D41: hash | E41: 14,14 | F41: 196 | G41: 530 | H41: 369 | I41: 101 | J41: 72428300 | L41: =IF(AND(ISNUMBER(I41),ISNUMBER(G41)),I41/G41,"") | M41: =IF(AND(ISNUMBER(I41),ISNUMBER(H41)),I41/H41,"") | N41: =IF(AND(ISNUMBER(H41),ISNUMBER(G41)),H41/G41,"") | O41: =IF(AND(ISNUMBER(J41),ISNUMBER(G41)),J41/G41,"") | P41: =IF(L41="","n/a",IF(L41<0.95,"Lead",IF(L41>1.05,"Lag","Parity"))) | Q41: =IF(M41="","n/a",IF(M41<0.95,"Lead",IF(M41>1.05,"Lag","Parity"))) | R41: ok | S41: ok | T41: rows-v1 | U41: 420 | V41: 168 | W41: 473.1 | X41: 101.5 | Y41: 371.6 | Z41: 288.3 | AB41: yes
...

Sheet Like-for-like
A1: Beryl native vs hand-written C under identical terms (sq2x2)
A2: Hand C: same beryl_kernel ABI, compile-time shape, int32 types, timing harness and clang flags. Ratio below 1.00x = Beryl faster.
A4: Pattern | B4: Cap (bytes) | C4: Objective | D4: Plan | E4: Mults | F4: Scratch B | G4: Beryl ns | H4: Hand C ns | I4: Beryl / hand C | J4: Verdict
A5: hash | B5: 0 | C5: multiplication_ops | D5: inline-v1 | E5: 900 | F5: 0 | G5: 281 | H5: 311 | I5: =IF(AND(ISNUMBER(G5),ISNUMBER(H5)),G5/H5,"") | J5: =IF(I5="","n/a",IF(I5<0.95,"Lead",IF(I5>1.05,"Lag","Parity")))
A6: hash | B6: 16 | C6: multiplication_ops | D6: inline-v1 | E6: 900 | F6: 0 | G6: 276 | H6: 312 | I6: =IF(AND(ISNUMBER(G6),ISNUMBER(H6)),G6/H6,"") | J6: =IF(I6="","n/a",IF(I6<0.95,"Lead",IF(I6>1.05,"Lag","Parity")))
A7: hash | B7: 32 | C7: multiplication_ops | D7: inline-v1 | E7: 900 | F7: 0 | G7: 275 | H7: 313 | I7: =IF(AND(ISNUMBER(G7),ISNUMBER(H7)),G7/H7,"") | J7: =IF(I7="","n/a",IF(I7<0.95,"Lead",IF(I7>1.05,"Lag","Parity")))
A8: hash | B8: 64 | C8: multiplication_ops | D8: inline-v1 | E8: 900 | F8: 0 | G8: 275 | H8: 310 | I8: =IF(AND(ISNUMBER(G8),ISNUMBER(H8)),G8/H8,"") | J8: =IF(I8="","n/a",IF(I8<0.95,"Lead",IF(I8>1.05,"Lag","Parity")))
A9: hash | B9: 128 | C9: multiplication_ops | D9: rows2-v1 | E9: 256 | F9: 128 | G9: 156 | H9: 311 | I9: =IF(AND(ISNUMBER(G9),ISNUMBER(H9)),G9/H9,"") | J9: =IF(I9="","n/a",IF(I9<0.95,"Lead",IF(I9>1.05,"Lag","Parity")))
A10: hash | B10: 1024 | C10: multiplication_ops | D10: rows2-v1 | E10: 256 | F10: 128 | G10: 157 | H10: 312 | I10: =IF(AND(ISNUMBER(G10),ISNUMBER(H10)),G10/H10,"") | J10: =IF(I10="","n/a",IF(I10<0.95,"Lead",IF(I10>1.05,"Lag","Parity")))
A11: hash | B11: 16 | C11: plan_workspace_bytes | D11: inline-v1 | E11: 900 | F11: 0 | G11: 275 | H11: 310 | I11: =IF(AND(ISNUMBER(G11),ISNUMBER(H11)),G11/H11,"") | J11: =IF(I11="","n/a",IF(I11<0.95,"Lead",IF(I11>1.05,"Lag","Parity")))
A12: hash | B12: 32 | C12: plan_workspace_bytes | D12: inline-v1 | E12: 900 | F12: 0 | G12: 276 | H12: 310 | I12: =IF(AND(ISNUMBER(G12),ISNUMBER(H12)),G12/H12,"") | J12: =IF(I12="","n/a",IF(I12<0.95,"Lead",IF(I12>1.05,"Lag","Parity")))
A13: hash | B13: 64 | C13: plan_workspace_bytes | D13: inline-v1 | E13: 900 | F13: 0 | G13: 280 | H13: 311 | I13: =IF(AND(ISNUMBER(G13),ISNUMBER(H13)),G13/H13,"") | J13: =IF(I13="","n/a",IF(I13<0.95,"Lead",IF(I13>1.05,"Lag","Parity")))
A14: hash | B14: 128 | C14: plan_workspace_bytes | D14: inline-v1 | E14: 900 | F14: 0 | G14: 277 | H14: 311 | I14: =IF(AND(ISNUMBER(G14),ISNUMBER(H14)),G14/H14,"") | J14: =IF(I14="","n/a",IF(I14<0.95,"Lead",IF(I14>1.05,"Lag","Parity")))
A15: hash | B15: 1024 | C15: plan_workspace_bytes | D15: inline-v1 | E15: 900 | F15: 0 | G15: 275 | H15: 311 | I15: =IF(AND(ISNUMBER(G15),ISNUMBER(H15)),G15/H15,"") | J15: =IF(I15="","n/a",IF(I15<0.95,"Lead",IF(I15>1.05,"Lag","Parity")))
A16: ramp | B16: 0 | C16: multiplication_ops | D16: inline-v1 | E16: 900 | F16: 0 | G16: 282 | H16: 310 | I16: =IF(AND(ISNUMBER(G16),ISNUMBER(H16)),G16/H16,"") | J16: =IF(I16="","n/a",IF(I16<0.95,"Lead",IF(I16>1.05,"Lag","Parity")))
... A20: ramp | B20: 128 | C20: multiplication_ops | D20: rows2-v1 | E20: 256 | F20: 128 | G20: 158 | H20: 311 | I20: =IF(AND(ISNUMBER(G20),ISNUMBER(H20)),G20/H20,"") | J20: =IF(I20="","n/a",IF(I20<0.95,"Lead",IF(I20>1.05,"Lag","Parity")))
A21: ramp | B21: 1024 | C21: multiplication_ops | D21: rows2-v1 | E21: 256 | F21: 128 | G21: 158 | I21: =IF(AND(ISNUMBER(G21),ISNUMBER(H21)),G21/H21,"") | J21: =IF(I21="","n/a",IF(I21<0.95,"Lead",IF(I21>1.05,"Lag","Parity")))
A22: ramp | B22: 0 | C22: plan_workspace_bytes | D22: inline-v1 | E22: 900 | F22: 0 | G22: 288 | H22: 310 | I22: =IF(AND(ISNUMBER(G22),ISNUMBER(H22)),G22/H22,"") | J22: =IF(I22="","n/a",IF(I22<0.95,"Lead",IF(I22>1.05,"Lag","Parity")))
A23: ramp | B23: 16 | C23: plan_workspace_bytes | D23: inline-v1 | E23: 900 | F23: 0 | G23: 279 | H23: 316 | I23: =IF(AND(ISNUMBER(G23),ISNUMBER(H23)),G23/H23,"") | J23: =IF(I23="","n/a",IF(I23<0.95,"Lead",IF(I23>1.05,"Lag","Parity")))
A24: ramp | B24: 64 | C24: plan_workspace_bytes | D24: inline-v1 | E24: 900 | F24: 0 | G24: 275 | H24: 311 | I24: =IF(AND(ISNUMBER(G24),ISNUMBER(H24)),G24/H24,"") | J24: =IF(I24="","n/a",IF(I24<0.95,"Lead",IF(I24>1.05,"Lag","Parity")))
A25: ramp | B25: 1024 | C25: plan_workspace_bytes | D25: inline-v1 | E25: 900 | F25: 0 | G25: 276 | H25: 310 | I25: =IF(AND(ISNUMBER(G25),ISNUMBER(H25)),G25/H25,"") | J25: =IF(I25="","n/a",IF(I25<0.95,"Lead",IF(I25>1.05,"Lag","Parity")))
A26: max | B26: 0 | C26: multiplication_ops | D26: inline-v1 | E26: 900 | F26: 0 | G26: 276 | H26: 311 | I26: =IF(AND(ISNUMBER(G26),ISNUMBER(H26)),G26/H26,"") | J26: =IF(I26="","n/a",IF(I26<0.95,"Lead",IF(I26>1.05,"Lag","Parity")))
A27: max | B27: 16 | C27: multiplication_ops | D27: inline-v1 | E27: 900 | F27: 0 | G27: 281 | H27: 321 | I27: =IF(AND(ISNUMBER(G27),ISNUMBER(H27)),G27/H27,"") | J27: =IF(I27="","n/a",IF(I27<0.95,"Lead",IF(I27>1.05,"Lag","Parity")))
A28: max | B28: 32 | C28: multiplication_ops | D28: inline-v1 | E28: 900 | F28: 0 | G28: 276 | H28: 312 | I28: =IF(AND(ISNUMBER(G28),ISNUMBER(H28)),G28/H28,"") | J28: =IF(I28="","n/a",IF(I28<0.95,"Lead",IF(I28>1.05,"Lag","Parity")))
A29: max | B29: 64 | C29: multiplication_ops | D29: inline-v1 | E29: 900 | F29: 0 | G29: 276 | H29: 311 | I29: =IF(AND(ISNUMBER(G29),ISNUMBER(H29)),G29/H29,"") | J29: =IF(I29="","n/a",IF(I29<0.95,"Lead",IF(I29>1.05,"Lag","Parity")))
A30: max | B30: 128 | C30: multiplication_ops | D30: rows2-v1 | E30: 256 | F30: 128 | G30: 158 | H30: 314 | I30: =IF(AND(ISNUMBER(G30),ISNUMBER(H30)),G30/H30,"") | J30: =IF(I30="","n/a",IF(I30<0.95,"Lead",IF(I30>1.05,"Lag","Parity")))
A31: max | B31: 1024 | C31: multiplication_ops | D31: rows2-v1 | E31: 256 | F31: 128 | G31: 157 | H31: 312 | I31: =IF(AND(ISNUMBER(G31),ISNUMBER(H31)),G31/H31,"") | J31: =IF(I31="","n/a",IF(I31<0.95,"Lead",IF(I31>1.05,"Lag","Parity")))
A32: max | B32: 0 | C32: plan_workspace_bytes | D32: inline-v1 | E32: 900 | F32: 0 | G32: 277 | H32: 310 | I32: =IF(AND(ISNUMBER(G32),ISNUMBER(H32)),G32/H32,"") | J32: =IF(I32="","n/a",IF(I32<0.95,"Lead",IF(I32>1.05,"Lag","Parity")))
A33: max | B33: 16 | C33: plan_workspace_bytes | D33: inline-v1 | E33: 900 | F33: 0 | G33: 275 | H33: 310 | I33: =IF(AND(ISNUMBER(G33),ISNUMBER(H33)),G33/H33,"") | J33: =IF(I33="","n/a",IF(I33<0.95,"Lead",IF(I33>1.05,"Lag","Parity")))
... A36: max | B36: 1024 | C36: plan_workspace_bytes | D36: inline-v1 | E36: 900 | F36: 0 | G36: 279 | H36: 314 | I36: =IF(AND(ISNUMBER(G36),ISNUMBER(H36)),G36/H36,"") | J36: =IF(I36="","n/a",IF(I36<0.95,"Lead",IF(I36>1.05,"Lag","Parity")))
A38: Average, inline plan | D38: inline-v1 | G38: =AVERAGEIF(D5:D36,"inline-v1",G5:G36) | H38: =AVERAGEIF(D5:D36,"inline-v1",H5:H36) | I38: =IFERROR(G38/H38,"")
A39: Average, row-reuse plan | D39: rows2-v1 | G39: =AVERAGEIF(D5:D36,"rows2-v1",G5:G36) | H39: =AVERAGEIF(D5:D36,"rows2-v1",H5:H36) | I39: =IFERROR(G39/H39,"")

Sheet Plan sweep
A1: One program, different storage limits: the planner picks a different legal schedule
A2: sq2x2 15x15. Every selected plan is independently checked; the result never changes, only the schedule.
A4: Backend | B4: Pattern | C4: Cap (bytes) | D4: Objective | E4: Plan | F4: Mults | G4: Scratch B | H4: Time ns | I4: Interp. pipeline ms | J4: Mults saved vs inline
A5: Beryl interpreter | B5: hash | C5: 0 | D5: multiplication_ops | E5: inline-v1 | F5: 900 | G5: 0 | H5: 192201300 | I5: 557 | J5: =IFERROR(1-F5/900,"")
A6: Beryl native | B6: hash | C6: 0 | D6: multiplication_ops | E6: inline-v1 | F6: 900 | G6: 0 | H6: 281 | J6: =IFERROR(1-F6/900,"")
A7: Beryl interpreter | B7: hash | C7: 16 | D7: multiplication_ops | E7: inline-v1 | F7: 900 | G7: 0 | H7: 88828900 | I7: 256 | J7: =IFERROR(1-F7/900,"")
A8: Beryl native | B8: hash | C8: 16 | D8: multiplication_ops | E8: inline-v1 | F8: 900 | G8: 0 | H8: 276 | J8: =IFERROR(1-F8/900,"")
A9: Beryl interpreter | B9: hash | C9: 32 | D9: multiplication_ops | E9: inline-v1 | F9: 900 | G9: 0 | H9: 91415900 | I9: 254.9 | J9: =IFERROR(1-F9/900,"")
A10: Beryl native | B10: hash | C10: 32 | D10: multiplication_ops | E10: inline-v1 | F10: 900 | G10: 0 | H10: 275 | J10: =IFERROR(1-F10/900,"")
A11: Beryl interpreter | B11: hash | C11: 64 | D11: multiplication_ops | E11: inline-v1 | F11: 900 | G11: 0 | H11: 94974700 | I11: 256.9 | J11: =IFERROR(1-F11/900,"")
A12: Beryl native | B12: hash | C12: 64 | D12: multiplication_ops | E12: inline-v1 | F12: 900 | G12: 0 | H12: 275 | J12: =IFERROR(1-F12/900,"")
A13: Beryl interpreter | B13: hash | C13: 128 | D13: multiplication_ops | E13: rows2-v1 | F13: 256 | G13: 128 | H13: 76590700 | I13: 264.6 | J13: =IFERROR(1-F13/900,"")
A14: Beryl native | B14: hash | C14: 128 | D14: multiplication_ops | E14: rows2-v1 | F14: 256 | G14: 128 | H14: 156 | J14: =IFERROR(1-F14/900,"")
A15: Beryl interpreter | B15: hash | C15: 1024 | D15: multiplication_ops | E15: rows2-v1 | F15: 256 | G15: 128 | H15: 80205700 | I15: 272.2 | J15: =IFERROR(1-F15/900,"")
A16: Beryl native | B16: hash | C16: 1024 | D16: multiplication_ops | E16: rows2-v1 | F16: 256 | G16: 128 | H16: 157 | J16: =IFERROR(1-F16/900,"")
A17: Beryl interpreter | B17: hash | C17: 0 | D17: plan_workspace_bytes | E17: inline-v1 | F17: 900 | G17: 0 | H17: 90774900 | I17: 256.3 | J17: =IFERROR(1-F17/900,"")
A18: Beryl interpreter | B18: hash | C18: 16 | D18: plan_workspace_bytes | E18: inline-v1 | F18: 900 | G18: 0 | H18: 97558600 | I18: 274.5 | J18: =IFERROR(1-F18/900,"")
A19: Beryl native | B19: hash | C19: 16 | D19: plan_workspace_bytes | E19: inline-v1 | F19: 900 | G19: 0 | H19: 275 | J19: =IFERROR(1-F19/900,"")
A20: Beryl interpreter | B20: hash | C20: 32 | D20: plan_workspace_bytes | E20: inline-v1 | F20: 900 | G20: 0 | H20: 100419000 | I20: 265.4 | J20: =IFERROR(1-F20/900,"")
A21: Beryl native | B21: hash | C21: 32 | D21: plan_workspace_bytes | E21: inline-v1 | F21: 900 | G21: 0 | H21: 276 | J21: =IFERROR(1-F21/900,"")
A22: Beryl interpreter | B22: hash | C22: 64 | D22: plan_workspace_bytes | E22: inline-v1 | F22: 900 | G22: 0 | H22: 90241700 | I22: 252.8 | J22: =IFERROR(1-F22/900,"")
A23: Beryl native | B23: hash | C23: 64 | D23: plan_workspace_bytes | E23: inline-v1 | F23: 900 | G23: 0 | H23: 280 | J23: =IFERROR(1-F23/900,"")
A24: Beryl interpreter | B24: hash | C24: 128 | D24: plan_workspace_bytes | E24: inline-v1 | F24: 900 | G24: 0 | H24: 91169500 | I24: 268.1 | J24: =IFERROR(1-F24/900,"")
A25: Beryl native | B25: hash | C25: 128 | D25: plan_workspace_bytes | E25: inline-v1 | F25: 900 | G25: 0 | H25: 277 | J25: =IFERROR(1-F25/900,"")
A26: Beryl interpreter | B26: hash | C26: 1024 | D26: plan_workspace_bytes | E26: inline-v1 | F26: 900 | G26: 0 | H26: 94466600 | I26: 284.8 | J26: =IFERROR(1-F26/900,"")
A27: Beryl native | B27: hash | C27: 1024 | D27: plan_workspace_bytes | E27: inline-v1 | F27: 900 | G27: 0 | H27: 275 | J27: =IFERROR(1-F27/900,"")
A28: Beryl interpreter | B28: ramp | C28: 0 | D28: multiplication_ops | E28: inline-v1 | F28: 900 | G28: 0 | H28: 103627300 | I28: 289.3 | J28: =IFERROR(1-F28/900,"")
A29: Beryl native | B29: ramp | C29: 0 | D29: multiplication_ops | E29: inline-v1 | F29: 900 | G29: 0 | H29: 282 | J29: =IFERROR(1-F29/900,"")
A30: Beryl interpreter | B30: ramp | C30: 16 | D30: multiplication_ops | E30: inline-v1 | F30: 900 | G30: 0 | H30: 94414400 | I30: 263.3 | J30: =IFERROR(1-F30/900,"")
A31: Beryl native | B31: ramp | C31: 16 | D31: multiplication_ops | E31: inline-v1 | F31: 900 | G31: 0 | H31: 276 | J31: =IFERROR(1-F31/900,"")
A32: Beryl interpreter | B32: ramp | C32: 32 | D32: multiplication_ops | E32: inline-v1 | F32: 900 | G32: 0 | H32: 90948100 | I32: 253.9 | J32: =IFERROR(1-F32/900,"")
A33: Beryl native | B33: ramp | C33: 32 | D33: multiplication_ops | E33: inline-v1 | F33: 900 | G33: 0 | H33: 276 | J33: =IFERROR(1-F33/900,"")
A34: Beryl interpreter | B34: ramp | C34: 64 | D34: multiplication_ops | E34: inline-v1 | F34: 900 | G34: 0 | H34: 90738200 | I34: 252.5 | J34: =IFERROR(1-F34/900,"")
A35: Beryl native | B35: ramp | C35: 64 | D35: multiplication_ops | E35: inline-v1 | F35: 900 | G35: 0 | H35: 276 | J35: =IFERROR(1-F35/900,"")
A36: Beryl interpreter | B36: ramp | C36: 128 | D36: multiplication_ops | E36: rows2-v1 | F36: 256 | G36: 128 | H36: 71303100 | I36: 252 | J36: =IFERROR(1-F36/900,"")
A37: Beryl native | B37: ramp | C37: 128 | D37: multiplication_ops | E37: rows2-v1 | F37: 256 | G37: 128 | H37: 158 | J37: =IFERROR(1-F37/900,"")
A38: Beryl interpreter | B38: ramp | C38: 1024 | D38: multiplication_ops | E38: rows2-v1 | F38: 256 | G38: 128 | H38: 74607000 | I38: 265 | J38: =IFERROR(1-F38/900,"")
A39: Beryl native | B39: ramp | C39: 1024 | D39: multiplication_ops | E39: rows2-v1 | F39: 256 | G39: 128 | H39: 158 | J39: =IFERROR(1-F39/900,"")
A40: Beryl interpreter | B40: ramp | C40: 0 | D40: plan_workspace_bytes | E40: inline-v1 | F40: 900 | G40: 0 | H40: 107442300 | I40: 307.4 | J40: =IFERROR(1-F40/900,"")
A41: Beryl native | B41: ramp | C41: 0 | D41: plan_workspace_bytes | E41: inline-v1 | F41: 900 | G41: 0 | H41: 288 | J41: =IFERROR(1-F41/900,"")
...

Sheet Interpreter phases
A1: Checked interpreter: time per phase (ms), small size, hash pattern
A2: select = generate and independently check every candidate plan; execute = fresh re-check plus interpretation; reference = independent source evaluation.
A4: Kernel | B4: Size | C4: Parse | D4: Admit | E4: Select | F4: Execute | G4: Reference | H4: Total | I4: Select share | J4: Execute share | K4: vs C (x)
A5: sq2x2 | B5: s | C5: 0.8 | D5: 0.17 | E5: 257.33 | F5: 118.95 | G5: 8.14 | H5: =SUM(C5:G5) | I5: =IFERROR(E5/H5,"") | J5: =IFERROR(F5/H5,"") | K5: =IFERROR(H5*1000000/422,"")
A6: stencil1d3 | B6: s | C6: 0.53 | D6: 0.18 | E6: 156.25 | F6: 59.26 | G6: 5.5 | H6: =SUM(C6:G6) | I6: =IFERROR(E6/H6,"") | J6: =IFERROR(F6/H6,"") | K6: =IFERROR(H6*1000000/206,"")
A7: box3x3 | B7: s | C7: 0.69 | D7: 0.18 | E7: 190.98 | F7: 89.71 | G7: 4.32 | H7: =SUM(C7:G7) | I7: =IFERROR(E7/H7,"") | J7: =IFERROR(F7/H7,"") | K7: =IFERROR(H7*1000000/482,"")
A8: laplace5 | B8: s | C8: 0.59 | D8: 0.17 | E8: 222.92 | F8: 79.86 | G8: 5.68 | H8: =SUM(C8:G8) | I8: =IFERROR(E8/H8,"") | J8: =IFERROR(F8/H8,"") | K8: =IFERROR(H8*1000000/227,"")
A9: conv3x3 | B9: s | C9: 0.56 | D9: 0.16 | E9: 210.62 | F9: 72.43 | G9: 4.85 | H9: =SUM(C9:G9) | I9: =IFERROR(E9/H9,"") | J9: =IFERROR(F9/H9,"") | K9: =IFERROR(H9*1000000/530,"")
A10: polymap | B10: s | C10: 0.41 | D10: 0.13 | E10: 156.04 | F10: 52.43 | G10: 3.83 | H10: =SUM(C10:G10) | I10: =IFERROR(E10/H10,"") | J10: =IFERROR(F10/H10,"") | K10: =IFERROR(H10*1000000/181,"")

Sheet Coverage
A1: What Beryl accepts today, per kernel and size (interpreter status, hash pattern)
A2: ok = admitted, proved and verified. unsupported = refused with a real diagnostic or not expressible in the grammar.
A4: Kernel | B4: Family | C4: Small | D4: Medium | E4: Large | F4: Blocking reason / missing features
A5: sq2x2 | B5: stencil-2d | C5: ok | D5: unsupported | E5: unsupported | F5: input exceeds 256 cells
A6: stencil1d3 | B6: stencil-1d | C6: ok | D6: unsupported | E6: unsupported | F6: input exceeds 256 cells
A7: box3x3 | B7: stencil-2d | C7: ok | D7: unsupported | E7: unsupported | F7: input exceeds 256 cells
A8: laplace5 | B8: stencil-2d | C8: ok | D8: unsupported | E8: unsupported | F8: input exceeds 256 cells
A9: conv3x3 | B9: stencil-2d | C9: ok | D9: unsupported | E9: unsupported | F9: input exceeds 256 cells
A10: life | B10: stencil-2d-cond | C10: unsupported | D10: unsupported | E10: unsupported | F10: bitwise ops, comparison, select/conditional
A11: polymap | B11: elementwise | C11: ok | D11: unsupported | E11: unsupported | F11: input exceeds 256 cells
A12: transpose | B12: layout | C12: unsupported | D12: unsupported | E12: unsupported | F12: requires exactly two shapes, one input, one producer and one output
A13: maxpool2 | B13: stencil-2d-cond | C13: unsupported | D13: unsupported | E13: unsupported | F13: max operator, strided index (2*r)
A14: sum | B14: reduction | C14: unsupported | D14: unsupported | E14: unsupported | F14: reduction syntax, i64 accumulators
A15: dot | B15: reduction | C15: unsupported | D15: unsupported | E15: unsupported | F15: reduction syntax, multiple inputs, i64 accumulators
... A18: matmul | B18: dense-linear-algebra | C18: unsupported | D18: unsupported | E18: unsupported | F18: reduction syntax, multiple inputs, tiling plans
A20: Accepted | C20: =COUNTIF(C5:C18,"ok") | D20: =COUNTIF(D5:D18,"ok") | E20: =COUNTIF(E5:E18,"ok") | F20: =C20+D20+E20&" of "&3*COUNTA(A5:A18)&" kernel/size combinations"
A22: Missing features, ranked by how many kernel/size combinations they block
A23: Feature | B23: Blocked combinations | C23: Kernels | F23: Notes
A24: inputs above 256 cells (m/l tiers) | B24: 12 | C24: box3x3, conv3x3, laplace5, polymap, sq2x2, stencil1d3 | F24: Needs the compact-loop proof work the handoff marks as blocked (C1/F1).
A25: reduction syntax | B25: 9 | C25: dot, matmul, sum | F25: sum, dot, matmul. A bounded fold over a literal axis would cover all three.
A26: i64 accumulators | B26: 6 | C26: dot, sum | F26: Reductions over 0..1023 inputs overflow i32 beyond ~2M terms.
A27: multiple inputs | B27: 6 | C27: dot, matmul | F27: dot and matmul read two tensors.
A28: bitwise ops | B28: 3 | C28: life
A29: comparison | B29: 3 | C29: life
A30: select/conditional | B30: 3 | C30: life | F30: Game of Life; also clamps and thresholds.
A31: permuted index reads | B31: 3 | C31: transpose
A32: layout plans | B32: 3 | C32: transpose
A33: max operator | B33: 3 | C33: maxpool2
A34: strided index (2*r) | B34: 3 | C34: maxpool2
A35: recurrence/scan syntax | B35: 3 | C35: scan
A36: i64 outputs | B36: 3 | C36: scan
A37: data-dependent indexing | B37: 3 | C37: hist
A38: scatter/accumulate | B38: 3 | C38: hist
A39: tiling plans | B39: 3 | C39: matmul

Sheet Lead-lag analysis
A1: Where Beryl leads, where it lags, and why
A2: Ratios are live medians from Kernel times (small size, all patterns). Confidence reflects how directly the cause was measured.
A4: Kernel | B4: Native / C | C4: Native / Rust | D4: Verdict | E4: Why | F4: What would change it | G4: Confidence
A5: conv3x3 | B5: =IFERROR(AVERAGEIFS('Kernel times'!$L$5:$L$130,'Kernel times'!$A$5:$A$130,A5,'Kernel times'!$C$5:$C$130,"s"),"") | C5: =IFERROR(AVERAGEIFS('Kernel times'!$M$5:$M$130,'Kernel times'!$A$5:$A$130,A5,'Kernel times'!$C$5:$C$130,"s"),"") | D5: =IF(B5="","n/a",IF(B5<0.95,"Lead",IF(B5>1.05,"Lag","Parity"))) | E5: The planner selected rows-v1: a rolling window of 3 producer rows, so each row sum is computed once and reused by three output rows (420 vs 784 multiplications). The C baseline evaluates all nine taps per output. Shape specialization and int32 stores also help. | F5: A hand-written separable C version would close most of the gap; the lead comes from the schedule, which Beryl chose automatically and proved correct. | G5: High
A6: sq2x2 | B6: =IFERROR(AVERAGEIFS('Kernel times'!$L$5:$L$130,'Kernel times'!$A$5:$A$130,A6,'Kernel times'!$C$5:$C$130,"s"),"") | C6: =IFERROR(AVERAGEIFS('Kernel times'!$M$5:$M$130,'Kernel times'!$A$5:$A$130,A6,'Kernel times'!$C$5:$C$130,"s"),"") | D6: =IF(B6="","n/a",IF(B6<0.95,"Lead",IF(B6>1.05,"Lag","Parity"))) | E6: Default request uses inline-v1 (no scratch), the same algorithm as the baselines; the small lead is shape specialization and int32 outputs. With 128+ bytes the row-reuse plan runs about 2x faster than hand C (256 vs 900 multiplications). | F6: See Like-for-like: at identical terms the inline plan is about 0.9x hand C. | G6: High (hand-C control)
A7: box3x3 | B7: =IFERROR(AVERAGEIFS('Kernel times'!$L$5:$L$130,'Kernel times'!$A$5:$A$130,A7,'Kernel times'!$C$5:$C$130,"s"),"") | C7: =IFERROR(AVERAGEIFS('Kernel times'!$M$5:$M$130,'Kernel times'!$A$5:$A$130,A7,'Kernel times'!$C$5:$C$130,"s"),"") | D7: =IF(B7="","n/a",IF(B7<0.95,"Lead",IF(B7>1.05,"Lag","Parity"))) | E7: Separable form, but at this size the inline plan is chosen under the default objective, so the lead is mostly compile-time shape and int32 stores against runtime-sized int64 baselines. | F7: A hand-C control for this kernel would split specialization from schedule; raising the cap lets rows-v1 reuse row sums. | G7: Medium
A8: laplace5 | B8: =IFERROR(AVERAGEIFS('Kernel times'!$L$5:$L$130,'Kernel times'!$A$5:$A$130,A8,'Kernel times'!$C$5:$C$130,"s"),"") | C8: =IFERROR(AVERAGEIFS('Kernel times'!$M$5:$M$130,'Kernel times'!$A$5:$A$130,A8,'Kernel times'!$C$5:$C$130,"s"),"") | D8: =IF(B8="","n/a",IF(B8<0.95,"Lead",IF(B8>1.05,"Lag","Parity"))) | E8: The producer is a copy of the input, so no schedule saves work; parity-plus comes from specialization and int32. | F8: Little headroom: a memory-bound five-point stencil. | G8: Medium
A9: stencil1d3 | B9: =IFERROR(AVERAGEIFS('Kernel times'!$L$5:$L$130,'Kernel times'!$A$5:$A$130,A9,'Kernel times'!$C$5:$C$130,"s"),"") | C9: =IFERROR(AVERAGEIFS('Kernel times'!$M$5:$M$130,'Kernel times'!$A$5:$A$130,A9,'Kernel times'!$C$5:$C$130,"s"),"") | D9: =IF(B9="","n/a",IF(B9<0.95,"Lead",IF(B9>1.05,"Lag","Parity"))) | E9: Written as a 1 x W grid; output stage is a copy, inline is optimal. Near parity with C; slightly behind Rust on some patterns. | F9: Compact loop form (not yet available for family kernels) would shrink code and allow vectorization. | G9: Medium
A10: polymap | B10: =IFERROR(AVERAGEIFS('Kernel times'!$L$5:$L$130,'Kernel times'!$A$5:$A$130,A10,'Kernel times'!$C$5:$C$130,"s"),"") | C10: =IFERROR(AVERAGEIFS('Kernel times'!$M$5:$M$130,'Kernel times'!$A$5:$A$130,A10,'Kernel times'!$C$5:$C$130,"s"),"") | D10: =IF(B10="","n/a",IF(B10<0.95,"Lead",IF(B10>1.05,"Lag","Parity"))) | E10: Lag. Family kernels lower to fully unrolled straight-line C (about 3,400 statements, 147 KB) plus a range check of all 256 inputs on every call; the C baseline is a short loop the compiler vectorizes. | F10: Extend compact loop programs to family kernels, and vectorize the input range check (min/max reduction). | G10: Medium (cause inferred from generated code; not profiled)
A12: Cross-cutting
A13: Interpreter (all kernels) | E13: About 5 orders of magnitude slower than C by design: each request decodes the plan, re-proves it (fresh admission, symbolic checking of every operation) and interprets it in Python. Proof dominates; interpretation is a few ms. | F13: Cache checked plans per session by exact source and plan digest, or share source derivation across candidates (about 45 ms).
A14: Coverage (22 of 28 suite cases, 36 of 42 combinations) | E14: All medium/large sizes exceed the 256-cell limit; 8 kernels need missing language features. | F14: See Coverage and the roadmap: reductions unlock 3 kernels; lifting the size limit unlocks 12 combinations.
A15: Cold compile (0.3-0.76 s) | E15: About 90-110 ms Axiom check+emit, then the C compiler and linker. sq2x2 uses compact loop C and compiles in about 0.3 s; family kernels emit fully unrolled C and take 0.4-0.76 s (clang alone 230-510 ms). The C/Rust baselines build in 1.4 s / 1.8 s but once for all sizes; Beryl compiles per program and shape. | F15: Compact loops for family kernels; cache native artifacts by digest; the Wasm path needs no C compiler.
A16: Rust vs C (context) | E16: Rust trails C on several kernels here (for example sq2x2), most likely bounds checks and the closure-based window helper in the baseline code. | F16: Not a Beryl issue; recorded so ratios against Rust are read correctly.

Sheet Improvement roadmap
A1: What to improve next, tied to the evidence
A2: Impact and effort are estimates (H/M/L). Score = impact x 3 - effort, computed live.
A4: # | B4: Improvement | C4: Area | D4: Evidence from this run | E4: Expected effect | F4: Impact (1-3) | G4: Effort (1-3) | H4: Score
A5: 1 | B5: Compact loop programs for window-stencil kernels | C5: Native codegen | D5: polymap lags C 1.2x; family kernels emit 3,400+ unrolled statements and compile in 0.4-0.76 s vs 0.3 s for compact sq2x2. | E5: Smaller C, vectorizable loops, faster compile; likely flips polymap to a lead. | F5: 3 | G5: 2 | H5: =F5*3-G5
A6: 2 | B6: Reduction syntax (bounded fold over a literal axis) with i64 accumulators | C6: Language | D6: sum, dot, matmul unsupported at every size (9 combinations). | E6: +3 kernels at small size; opens matmul tiling plans as a new storage trade-off. | F6: 3 | G6: 3 | H6: =F6*3-G6
A7: 3 | B7: Lift the 256-cell limit (compact-loop proof gate C1/F1) | C7: Proof / scale | D7: Every medium and large case is refused: 12 combinations for already-admitted kernels. | E7: Unblocks realistic sizes; the main remaining research gate. | F7: 3 | G7: 3 | H7: =F7*3-G7
A8: 4 | B8: Vectorized input range check in generated C | C8: Native codegen | D8: Every native call scans all inputs before computing (256 compares). | E8: Small constant gain on every kernel; keeps the semantics exactly. | F8: 2 | G8: 1 | H8: =F8*3-G8
A9: 5 | B9: Hand-C controls for every admitted kernel | C9: Benchmark honesty | D9: Only sq2x2 has a like-for-like control; other leads mix schedule and specialization. | E9: Separates what Beryl chooses (schedule) from how it compiles (specialization). | F9: 2 | G9: 1 | H9: =F9*3-G9
A10: 6 | B10: Conditional/select, comparison and max operators | C10: Language | D10: life and maxpool2 not expressible (6 combinations). | E10: +2 kernels; also clamps and thresholds. | F10: 2 | G10: 2 | H10: =F10*3-G10
A11: 7 | B11: Cache checked plans per session by exact digest | C11: Interpreter | D11: Interpreter re-proves every plan per request (~250-560 ms pipeline). | E11: Repeat playground runs drop to the interpretation cost; must keep the fresh-check rule explicit. | F11: 2 | G11: 2 | H11: =F11*3-G11
A12: 8 | B12: Fix the reject_profile benchmark case | C12: Benchmark | D12: Its box3x3 example is now an admitted family member, so the case no longer measures a rejection. | E12: Restores the rejection-latency measurement. | F12: 1 | G12: 1 | H12: =F12*3-G12
A13: 9 | B13: Update public README scope text before the next release | C13: Release | D13: Generated README still says "one exact i32 two-stage stencil". | E13: Accurate public claims (your decision; nothing is published). | F13: 1 | G13: 1 | H13: =F13*3-G13
A14: 10 | B14: Allow-list the dev build folder for Windows Application Control | C14: Environment | D14: 6 native runs blocked; test suite has random native failures. | E14: Complete native columns and stable tests (a machine setting for you to decide; never bypassed in code). | F14: 1 | G14: 1 | H14: =F14*3-G14

Sheet Method
A1: Environment, protocol and caveats
A3: Item | B3: Detail
A4: Run id | B4: 20261019T005748Z-73191bf
A5: Label | B5: full suite: Beryl interpreter + native vs C and Rust, s/m/l, 3 patterns
A6: Revision | B6: 73191bf224fce5022ea514f128e0b7855246bf95 on feat/bench-native (dirty)
A7: Started (UTC) | B7: 2026-10-19T00:57:48.821202+00:00
A8: Platform | B8: Windows-11-10.0.26200-SP0
A9: Processor | B9: AMD64 Family 23 Model 113 Stepping 0, AuthenticAMD, 8 logical CPUs
A10: Python | B10: 3.13.13
A11: C compiler | B11: clang version 22.1.6 (https://github.com/llvm/llvm-project.git fc4aad7b5db3fff421df9a9637605b9ca5667881)
A12: Rust compiler | B12: rustc 1.96.0 (ac68faa20 2026-05-25)
A13: Flags | B13: C -O3 -std=c11; Rust -C opt-level=3; Beryl native: same clang and flags as C, -fno-lto
A14: Settings | B14: min 200 ms timed per case, up to 1000 samples; sizes s, m, l; patterns hash, ramp, max
... A21: Source log | B21: bench/results/20261019T005748Z-73191bf.jsonl

Sheet Raw results
A1: Flattened analysis rows (one per kernel, size and pattern)
A3: kernel | B3: family | C3: tier | D3: pattern | E3: a | F3: b | G3: n_out | H3: c_ns | I3: rust_ns | J3: native_ns | K3: interp_ns | L3: hand_c_ns | M3: c_status | N3: rust_status | O3: native_status | P3: interp_status | Q3: native_plan | R3: native_mults | S3: native_scratch | T3: compile_ms | U3: axiom_compile_ms | V3: kernel_cc_ms | W3: link_ms | X3: pipeline_ms | Y3: diagnostic_code | Z3: verified
A4: sq2x2 | B4: stencil-2d | C4: s | D4: hash | E4: 15 | F4: 15 | G4: 225 | H4: 422 | I4: 878 | J4: 305 | K4: 118945500 | L4: 430 | M4: ok | N4: ok | O4: ok | P4: ok | Q4: inline-v1 | R4: 900 | S4: 0 | T4: 567.2 | U4: 160 | V4: 267.6 | W4: 139.6 | X4: 391.5 | Z4: yes
A5: sq2x2 | B5: stencil-2d | C5: s | D5: max | E5: 15 | F5: 15 | G5: 225 | H5: 513 | I5: 897 | J5: 407 | K5: 129022600 | L5: 420 | M5: ok | N5: ok | O5: ok | P5: ok | Q5: inline-v1 | R5: 900 | S5: 0 | T5: 367.3 | U5: 124 | V5: 151.6 | W5: 91.8 | X5: 323.7 | Z5: yes
A6: sq2x2 | B6: stencil-2d | C6: s | D6: ramp | E6: 15 | F6: 15 | G6: 225 | H6: 388 | I6: 719 | J6: 364 | K6: 118987300 | L6: 342 | M6: ok | N6: ok | O6: ok | P6: ok | Q6: inline-v1 | R6: 900 | S6: 0 | T6: 410.1 | U6: 121.2 | V6: 174.3 | W6: 114.6 | X6: 325.8 | Z6: yes
A7: sq2x2 | B7: stencil-2d | C7: m | D7: hash | E7: 255 | F7: 255 | G7: 65025 | H7: 148700 | I7: 200375 | M7: ok | N7: ok | O7: unsupported | P7: unsupported | Y7: UNSUPPORTED_PROFILE | Z7: yes
A8: sq2x2 | B8: stencil-2d | C8: m | D8: max | E8: 255 | F8: 255 | G8: 65025 | H8: 156225 | I8: 198712 | M8: ok | N8: ok | O8: unsupported | P8: unsupported | Y8: UNSUPPORTED_PROFILE | Z8: yes
A9: sq2x2 | B9: stencil-2d | C9: m | D9: ramp | E9: 255 | F9: 255 | G9: 65025 | H9: 144312 | I9: 185712 | M9: ok | N9: ok | O9: unsupported | P9: unsupported | Y9: UNSUPPORTED_PROFILE | Z9: yes
A10: sq2x2 | B10: stencil-2d | C10: l | D10: hash | E10: 2047 | F10: 2047 | G10: 4190209 | H10: 8373650 | I10: 12651850 | M10: ok | N10: ok | O10: unsupported | P10: unsupported | Y10: UNSUPPORTED_PROFILE | Z10: yes
A11: sq2x2 | B11: stencil-2d | C11: l | D11: max | E11: 2047 | F11: 2047 | G11: 4190209 | H11: 10026850 | I11: 13721300 | M11: ok | N11: ok | O11: unsupported | P11: unsupported | Y11: UNSUPPORTED_PROFILE | Z11: yes
A12: sq2x2 | B12: stencil-2d | C12: l | D12: ramp | E12: 2047 | F12: 2047 | G12: 4190209 | H12: 8003000 | I12: 13138300 | M12: ok | N12: ok | O12: unsupported | P12: unsupported | Y12: UNSUPPORTED_PROFILE | Z12: yes
A13: stencil1d3 | B13: stencil-1d | C13: s | D13: hash | E13: 254 | F13: 0 | G13: 254 | H13: 206 | I13: 162 | J13: 164 | K13: 59255900 | M13: ok | N13: ok | O13: ok | P13: ok | Q13: inline-v1 | R13: 254 | S13: 0 | T13: 758.8 | U13: 104 | V13: 510.9 | W13: 143.8 | X13: 220.8 | Z13: yes
A14: stencil1d3 | B14: stencil-1d | C14: s | D14: max | E14: 254 | F14: 0 | G14: 254 | H14: 187 | I14: 205 | K14: 55730500 | M14: ok | N14: ok | O14: blocked | P14: ok | X14: 202.4 | Y14: OS_LAUNCH_REFUSED | Z14: yes
A15: stencil1d3 | B15: stencil-1d | C15: s | D15: ramp | E15: 254 | F15: 0 | G15: 254 | H15: 162 | I15: 155 | J15: 162 | K15: 44709000 | M15: ok | N15: ok | O15: ok | P15: ok | Q15: inline-v1 | R15: 254 | S15: 0 | T15: 404.6 | U15: 63.5 | V15: 242.5 | W15: 98.6 | X15: 181.6 | Z15: yes
A16: stencil1d3 | B16: stencil-1d | C16: m | D16: hash | E16: 65534 | F16: 0 | G16: 65534 | H16: 52643 | I16: 50351 | M16: ok | N16: ok | O16: unsupported | P16: unsupported | Y16: UNSUPPORTED_PROFILE | Z16: yes
A17: stencil1d3 | B17: stencil-1d | C17: m | D17: max | E17: 65534 | F17: 0 | G17: 65534 | H17: 45625 | I17: 39821 | M17: ok | N17: ok | O17: unsupported | P17: unsupported | Y17: UNSUPPORTED_PROFILE | Z17: yes
A18: stencil1d3 | B18: stencil-1d | C18: m | D18: ramp | E18: 65534 | F18: 0 | G18: 65534 | H18: 44259 | I18: 51103 | M18: ok | N18: ok | O18: unsupported | P18: unsupported | Y18: UNSUPPORTED_PROFILE | Z18: yes
A19: stencil1d3 | B19: stencil-1d | C19: l | D19: hash | E19: 4194302 | F19: 0 | G19: 4194302 | H19: 4415300 | I19: 4491700 | M19: ok | N19: ok | O19: unsupported | P19: unsupported | Y19: UNSUPPORTED_PROFILE | Z19: yes
A20: stencil1d3 | B20: stencil-1d | C20: l | D20: max | E20: 4194302 | F20: 0 | G20: 4194302 | H20: 5291400 | I20: 5853100 | M20: ok | N20: ok | O20: unsupported | P20: unsupported | Y20: UNSUPPORTED_PROFILE | Z20: yes
A21: stencil1d3 | B21: stencil-1d | C21: l | D21: ramp | E21: 4194302 | F21: 0 | G21: 4194302 | H21: 4595350 | I21: 4006400 | M21: ok | N21: ok | O21: unsupported | P21: unsupported | Y21: UNSUPPORTED_PROFILE | Z21: yes
A22: box3x3 | B22: stencil-2d | C22: s | D22: hash | E22: 14 | F22: 14 | G22: 196 | H22: 482 | I22: 502 | J22: 311 | K22: 89714900 | M22: ok | N22: ok | O22: ok | P22: ok | Q22: inline-v1 | R22: 0 | S22: 0 | T22: 604.4 | U22: 96.3 | V22: 402.8 | W22: 105.3 | X22: 286.1 | Z22: yes
A23: box3x3 | B23: stencil-2d | C23: s | D23: max | E23: 14 | F23: 14 | G23: 196 | H23: 346 | I23: 419 | J23: 307 | K23: 88115200 | M23: ok | N23: ok | O23: ok | P23: ok | Q23: inline-v1 | R23: 0 | S23: 0 | T23: 497.7 | U23: 85.5 | V23: 328.3 | W23: 83.9 | X23: 282.4 | Z23: yes
